Workbook

Sheet 1. Assumptions
A1: Landed Cost & Margin Scenario Model — Assumptions & Drivers
A2: Planning horizon: Sep 2026 – Jun 2027. BLUE cells are inputs — edit them and every tab recalculates. Base / Moderate / Severe are downside stress cases (Base = mild pressure, Severe = worst case).
A4: SCENARIO DRIVERS
A5: Driver | B5: Plan | C5: Base | D5: Moderate | E5: Severe | F5: Unit | G5: Notes
A6: AUD/USD spot rate | B6: 0.66 | C6: 0.655 | D6: 0.62 | E6: 0.58 | F6: USD per 1 AUD | G6: Lower = weaker AUD = dearer imports
A7: AUD per USD (= 1 / spot) | B7: =1/B6 | C7: =1/C6 | D7: =1/D6 | E7: =1/E6 | F7: AUD per 1 USD | G7: Derived. Every USD cost is multiplied by this.
A8: Air freight rate | B8: 6 | C8: 6.2 | D8: 7.5 | E8: 9 | F8: USD per kg | G8: Spot air out of origin
A9: Sea freight rate | B9: 180 | C9: 190 | D9: 260 | E9: 340 | F9: USD per CBM | G9: FCL-equivalent per cubic metre
A10: Import duty | B10: 0.05 | C10: 0.05 | D10: 0.05 | E10: 0.05 | F10: % of FOB | G10: Held flat across scenarios
A11: Insurance & handling | B11: 0.03 | C11: 0.03 | D11: 0.03 | E11: 0.03 | F11: % of FOB | G11: Held flat across scenarios
A12: Consumer spending vs plan | B12: 0 | C12: -0.02 | D12: -0.05 | E12: -0.11 | F12: % vs plan | G12: Macro driver of demand
A13: Air->sea substitution shift | B13: 0 | C13: 0 | D13: 0.1 | E13: 0.2 | F13: pp of units | G13: Defensive shift embedded in scenario
A15: DEMAND ELASTICITY BY SEGMENT
A16: Segment | B16: Elasticity | C16: demand % move per 1% spending move | G16: Notes
A17: Premium | B17: 1.5 | G17: Discretionary — most sensitive to spending
A18: Core | B18: 1 | G18: Moves roughly with the market
A19: Value | B19: 0.5 | G19: Defensive — customers trade down into it
A21: AGGREGATE MODEL BASIS (Margin Bridge & Levers)
A22: Item | B22: Value | F22: Unit | G22: Notes
A23: Total planned units (period) | B23: 480000 | F23: units | G23: Representative volume, Sep26-Jun27
A24: Planned ASP (avg selling price) | B24: 38 | F24: AUD/unit | G24: Blended across catalogue
A25: Avg FOB cost | B25: 12 | F25: USD/unit | G25: Representative average (cf. Tab 2 SKUs)
A26: Avg weight | B26: 0.9 | F26: kg/unit | G26: Drives air freight per unit
A27: Avg units per CBM | B27: 220 | F27: units/CBM | G27: Drives sea freight per unit
A28: Planned air share of units | B28: 0.35 | F28: % of units | G28: Balance ships by sea
A29: Price elasticity | B29: 0.8 | F29: vol% per 1% price | G29: For the price-passthrough lever

Sheet 2. Landed Cost Impact
A1: Landed Cost Impact — Air vs Sea, FX effect vs Freight effect
A2: All landed costs are AUD per unit. Effects are measured vs Plan. Attribution order: FX first (revalue every USD cost at the scenario rate), then Freight (apply the scenario freight rate). FX Δ + Freight Δ = Total Δ, exactly.
A4: SKU MASTER (inputs)
A5: SKU Code | B5: Description | C5: FOB Cost (USD) | D5: Weight (kg) | E5: Units / CBM
A6: SKU-001 | B6: Compact appliance | C6: 24 | D6: 2.1 | E6: 60
A7: SKU-002 | B7: Kitchen accessory | C7: 6.5 | D7: 0.4 | E7: 480
A8: SKU-003 | B8: Homeware set | C8: 14 | D8: 1.8 | E8: 90
A9: SKU-004 | B9: Small electronic | C9: 32 | D9: 0.6 | E9: 300
A10: SKU-005 | B10: Textile goods | C10: 9 | D10: 1.2 | E10: 140
A11: SKU-006 | B11: Bulky furniture item | C11: 45 | D11: 8.5 | E11: 12
A13: AIR FREIGHT — Landed Cost per Unit (AUD)
A14: SKU | B14: Plan | C14: Base Landed | D14: Base FX Δ | E14: Base Freight Δ | F14: Base Total Δ | G14: Moderate Landed | H14: Moderate FX Δ | I14: Moderate Freight Δ | J14: Moderate Total Δ | K14: Severe Landed | L14: Severe FX Δ | M14: Severe Freight Δ | N14: Severe Total Δ
A15: =$A$6 | B15: ='1. Assumptions'!$B$7*($C$6*(1+'1. Assumptions'!$B$10+'1. Assumptions'!$B$11)+$D$6*'1. Assumptions'!$B$8) | C15: ='1. Assumptions'!$C$7*($C$6*(1+'1. Assumptions'!$B$10+'1. Assumptions'!$B$11)+$D$6*'1. Assumptions'!$C$8) | D15: ='1. Assumptions'!$C$7*($C$6*(1+'1. Assumptions'!$B$10+'1. Assumptions'!$B$11)+$D$6*'1. Assumptions'!$B$8)-$B$15 | E15: =C15-('1. Assumptions'!$C$7*($C$6*(1+'1. Assumptions'!$B$10+'1. Assumptions'!$B$11)+$D$6*'1. Assumptions'!$B$8)) | F15: =C15-$B$15 | G15: ='1. Assumptions'!$D$7*($C$6*(1+'1. Assumptions'!$B$10+'1. Assumptions'!$B$11)+$D$6*'1. Assumptions'!$D$8) | H15: ='1. Assumptions'!$D$7*($C$6*(1+'1. Assumptions'!$B$10+'1. Assumptions'!$B$11)+$D$6*'1. Assumptions'!$B$8)-$B$15 | I15: =G15-('1. Assumptions'!$D$7*($C$6*(1+'1. Assumptions'!$B$10+'1. Assumptions'!$B$11)+$D$6*'1. Assumptions'!$B$8)) | J15: =G15-$B$15 | K15: ='1. Assumptions'!$E$7*($C$6*(1+'1. Assumptions'!$B$10+'1. Assumptions'!$B$11)+$D$6*'1. Assumptions'!$E$8) | L15: ='1. Assumptions'!$E$7*($C$6*(1+'1. Assumptions'!$B$10+'1. Assumptions'!$B$11)+$D$6*'1. Assumptions'!$B$8)-$B$15 | M15: =K15-('1. Assumptions'!$E$7*($C$6*(1+'1. Assumptions'!$B$10+'1. Assumptions'!$B$11)+$D$6*'1. Assumptions'!$B$8)) | N15: =K15-$B$15
A16: =$A$7 | B16: ='1. Assumptions'!$B$7*($C$7*(1+'1. Assumptions'!$B$10+'1. Assumptions'!$B$11)+$D$7*'1. Assumptions'!$B$8) | C16: ='1. Assumptions'!$C$7*($C$7*(1+'1. Assumptions'!$B$10+'1. Assumptions'!$B$11)+$D$7*'1. Assumptions'!$C$8) | D16: ='1. Assumptions'!$C$7*($C$7*(1+'1. Assumptions'!$B$10+'1. Assumptions'!$B$11)+$D$7*'1. Assumptions'!$B$8)-$B$16 | E16: =C16-('1. Assumptions'!$C$7*($C$7*(1+'1. Assumptions'!$B$10+'1. Assumptions'!$B$11)+$D$7*'1. Assumptions'!$B$8)) | F16: =C16-$B$16 | G16: ='1. Assumptions'!$D$7*($C$7*(1+'1. Assumptions'!$B$10+'1. Assumptions'!$B$11)+$D$7*'1. Assumptions'!$D$8) | H16: ='1. Assumptions'!$D$7*($C$7*(1+'1. Assumptions'!$B$10+'1. Assumptions'!$B$11)+$D$7*'1. Assumptions'!$B$8)-$B$16 | I16: =G16-('1. Assumptions'!$D$7*($C$7*(1+'1. Assumptions'!$B$10+'1. Assumptions'!$B$11)+$D$7*'1. Assumptions'!$B$8)) | J16: =G16-$B$16 | K16: ='1. Assumptions'!$E$7*($C$7*(1+'1. Assumptions'!$B$10+'1. Assumptions'!$B$11)+$D$7*'1. Assumptions'!$E$8) | L16: ='1. Assumptions'!$E$7*($C$7*(1+'1. Assumptions'!$B$10+'1. Assumptions'!$B$11)+$D$7*'1. Assumptions'!$B$8)-$B$16 | M16: =K16-('1. Assumptions'!$E$7*($C$7*(1+'1. Assumptions'!$B$10+'1. Assumptions'!$B$11)+$D$7*'1. Assumptions'!$B$8)) | N16: =K16-$B$16
A17: =$A$8 | B17: ='1. Assumptions'!$B$7*($C$8*(1+'1. Assumptions'!$B$10+'1. Assumptions'!$B$11)+$D$8*'1. Assumptions'!$B$8) | C17: ='1. Assumptions'!$C$7*($C$8*(1+'1. Assumptions'!$B$10+'1. Assumptions'!$B$11)+$D$8*'1. Assumptions'!$C$8) | D17: ='1. Assumptions'!$C$7*($C$8*(1+'1. Assumptions'!$B$10+'1. Assumptions'!$B$11)+$D$8*'1. Assumptions'!$B$8)-$B$17 | E17: =C17-('1. Assumptions'!$C$7*($C$8*(1+'1. Assumptions'!$B$10+'1. Assumptions'!$B$11)+$D$8*'1. Assumptions'!$B$8)) | F17: =C17-$B$17 | G17: ='1. Assumptions'!$D$7*($C$8*(1+'1. Assumptions'!$B$10+'1. Assumptions'!$B$11)+$D$8*'1. Assumptions'!$D$8) | H17: ='1. Assumptions'!$D$7*($C$8*(1+'1. Assumptions'!$B$10+'1. Assumptions'!$B$11)+$D$8*'1. Assumptions'!$B$8)-$B$17 | I17: =G17-('1. Assumptions'!$D$7*($C$8*(1+'1. Assumptions'!$B$10+'1. Assumptions'!$B$11)+$D$8*'1. Assumptions'!$B$8)) | J17: =G17-$B$17 | K17: ='1. Assumptions'!$E$7*($C$8*(1+'1. Assumptions'!$B$10+'1. Assumptions'!$B$11)+$D$8*'1. Assumptions'!$E$8) | L17: ='1. Assumptions'!$E$7*($C$8*(1+'1. Assumptions'!$B$10+'1. Assumptions'!$B$11)+$D$8*'1. Assumptions'!$B$8)-$B$17 | M17: =K17-('1. Assumptions'!$E$7*($C$8*(1+'1. Assumptions'!$B$10+'1. Assumptions'!$B$11)+$D$8*'1. Assumptions'!$B$8)) | N17: =K17-$B$17
A18: =$A$9 | B18: ='1. Assumptions'!$B$7*($C$9*(1+'1. Assumptions'!$B$10+'1. Assumptions'!$B$11)+$D$9*'1. Assumptions'!$B$8) | C18: ='1. Assumptions'!$C$7*($C$9*(1+'1. Assumptions'!$B$10+'1. Assumptions'!$B$11)+$D$9*'1. Assumptions'!$C$8) | D18: ='1. Assumptions'!$C$7*($C$9*(1+'1. Assumptions'!$B$10+'1. Assumptions'!$B$11)+$D$9*'1. Assumptions'!$B$8)-$B$18 | E18: =C18-('1. Assumptions'!$C$7*($C$9*(1+'1. Assumptions'!$B$10+'1. Assumptions'!$B$11)+$D$9*'1. Assumptions'!$B$8)) | F18: =C18-$B$18 | G18: ='1. Assumptions'!$D$7*($C$9*(1+'1. Assumptions'!$B$10+'1. Assumptions'!$B$11)+$D$9*'1. Assumptions'!$D$8) | H18: ='1. Assumptions'!$D$7*($C$9*(1+'1. Assumptions'!$B$10+'1. Assumptions'!$B$11)+$D$9*'1. Assumptions'!$B$8)-$B$18 | I18: =G18-('1. Assumptions'!$D$7*($C$9*(1+'1. Assumptions'!$B$10+'1. Assumptions'!$B$11)+$D$9*'1. Assumptions'!$B$8)) | J18: =G18-$B$18 | K18: ='1. Assumptions'!$E$7*($C$9*(1+'1. Assumptions'!$B$10+'1. Assumptions'!$B$11)+$D$9*'1. Assumptions'!$E$8) | L18: ='1. Assumptions'!$E$7*($C$9*(1+'1. Assumptions'!$B$10+'1. Assumptions'!$B$11)+$D$9*'1. Assumptions'!$B$8)-$B$18 | M18: =K18-('1. Assumptions'!$E$7*($C$9*(1+'1. Assumptions'!$B$10+'1. Assumptions'!$B$11)+$D$9*'1. Assumptions'!$B$8)) | N18: =K18-$B$18
A19: =$A$10 | B19: ='1. Assumptions'!$B$7*($C$10*(1+'1. Assumptions'!$B$10+'1. Assumptions'!$B$11)+$D$10*'1. Assumptions'!$B$8) | C19: ='1. Assumptions'!$C$7*($C$10*(1+'1. Assumptions'!$B$10+'1. Assumptions'!$B$11)+$D$10*'1. Assumptions'!$C$8) | D19: ='1. Assumptions'!$C$7*($C$10*(1+'1. Assumptions'!$B$10+'1. Assumptions'!$B$11)+$D$10*'1. Assumptions'!$B$8)-$B$19 | E19: =C19-('1. Assumptions'!$C$7*($C$10*(1+'1. Assumptions'!$B$10+'1. Assumptions'!$B$11)+$D$10*'1. Assumptions'!$B$8)) | F19: =C19-$B$19 | G19: ='1. Assumptions'!$D$7*($C$10*(1+'1. Assumptions'!$B$10+'1. Assumptions'!$B$11)+$D$10*'1. Assumptions'!$D$8) | H19: ='1. Assumptions'!$D$7*($C$10*(1+'1. Assumptions'!$B$10+'1. Assumptions'!$B$11)+$D$10*'1. Assumptions'!$B$8)-$B$19 | I19: =G19-('1. Assumptions'!$D$7*($C$10*(1+'1. Assumptions'!$B$10+'1. Assumptions'!$B$11)+$D$10*'1. Assumptions'!$B$8)) | J19: =G19-$B$19 | K19: ='1. Assumptions'!$E$7*($C$10*(1+'1. Assumptions'!$B$10+'1. Assumptions'!$B$11)+$D$10*'1. Assumptions'!$E$8) | L19: ='1. Assumptions'!$E$7*($C$10*(1+'1. Assumptions'!$B$10+'1. Assumptions'!$B$11)+$D$10*'1. Assumptions'!$B$8)-$B$19 | M19: =K19-('1. Assumptions'!$E$7*($C$10*(1+'1. Assumptions'!$B$10+'1. Assumptions'!$B$11)+$D$10*'1. Assumptions'!$B$8)) | N19: =K19-$B$19
A20: =$A$11 | B20: ='1. Assumptions'!$B$7*($C$11*(1+'1. Assumptions'!$B$10+'1. Assumptions'!$B$11)+$D$11*'1. Assumptions'!$B$8) | C20: ='1. Assumptions'!$C$7*($C$11*(1+'1. Assumptions'!$B$10+'1. Assumptions'!$B$11)+$D$11*'1. Assumptions'!$C$8) | D20: ='1. Assumptions'!$C$7*($C$11*(1+'1. Assumptions'!$B$10+'1. Assumptions'!$B$11)+$D$11*'1. Assumptions'!$B$8)-$B$20 | E20: =C20-('1. Assumptions'!$C$7*($C$11*(1+'1. Assumptions'!$B$10+'1. Assumptions'!$B$11)+$D$11*'1. Assumptions'!$B$8)) | F20: =C20-$B$20 | G20: ='1. Assumptions'!$D$7*($C$11*(1+'1. Assumptions'!$B$10+'1. Assumptions'!$B$11)+$D$11*'1. Assumptions'!$D$8) | H20: ='1. Assumptions'!$D$7*($C$11*(1+'1. Assumptions'!$B$10+'1. Assumptions'!$B$11)+$D$11*'1. Assumptions'!$B$8)-$B$20 | I20: =G20-('1. Assumptions'!$D$7*($C$11*(1+'1. Assumptions'!$B$10+'1. Assumptions'!$B$11)+$D$11*'1. Assumptions'!$B$8)) | J20: =G20-$B$20 | K20: ='1. Assumptions'!$E$7*($C$11*(1+'1. Assumptions'!$B$10+'1. Assumptions'!$B$11)+$D$11*'1. Assumptions'!$E$8) | L20: ='1. Assumptions'!$E$7*($C$11*(1+'1. Assumptions'!$B$10+'1. Assumptions'!$B$11)+$D$11*'1. Assumptions'!$B$8)-$B$20 | M20: =K20-('1. Assumptions'!$E$7*($C$11*(1+'1. Assumptions'!$B$10+'1. Assumptions'!$B$11)+$D$11*'1. Assumptions'!$B$8)) | N20: =K20-$B$20
A21: Average | B21: =AVERAGE(B15:B20) | C21: =AVERAGE(C15:C20) | D21: =AVERAGE(D15:D20) | E21: =AVERAGE(E15:E20) | F21: =AVERAGE(F15:F20) | G21: =AVERAGE(G15:G20) | H21: =AVERAGE(H15:H20) | I21: =AVERAGE(I15:I20) | ... N21: =AVERAGE(N15:N20)
A24: SEA FREIGHT — Landed Cost per Unit (AUD)
A25: SKU | B25: Plan | C25: Base Landed | D25: Base FX Δ | E25: Base Freight Δ | F25: Base Total Δ | G25: Moderate Landed | H25: Moderate FX Δ | I25: Moderate Freight Δ | J25: Moderate Total Δ | K25: Severe Landed | L25: Severe FX Δ | M25: Severe Freight Δ | N25: Severe Total Δ
A26: =$A$6 | B26: ='1. Assumptions'!$B$7*($C$6*(1+'1. Assumptions'!$B$10+'1. Assumptions'!$B$11)+(1/$E$6)*'1. Assumptions'!$B$9) | C26: ='1. Assumptions'!$C$7*($C$6*(1+'1. Assumptions'!$B$10+'1. Assumptions'!$B$11)+(1/$E$6)*'1. Assumptions'!$C$9) | D26: ='1. Assumptions'!$C$7*($C$6*(1+'1. Assumptions'!$B$10+'1. Assumptions'!$B$11)+(1/$E$6)*'1. Assumptions'!$B$9)-$B$26 | E26: =C26-('1. Assumptions'!$C$7*($C$6*(1+'1. Assumptions'!$B$10+'1. Assumptions'!$B$11)+(1/$E$6)*'1. Assumptions'!$B$9)) | F26: =C26-$B$26 | G26: ='1. Assumptions'!$D$7*($C$6*(1+'1. Assumptions'!$B$10+'1. Assumptions'!$B$11)+(1/$E$6)*'1. Assumptions'!$D$9) | H26: ='1. Assumptions'!$D$7*($C$6*(1+'1. Assumptions'!$B$10+'1. Assumptions'!$B$11)+(1/$E$6)*'1. Assumptions'!$B$9)-$B$26 | I26: =G26-('1. Assumptions'!$D$7*($C$6*(1+'1. Assumptions'!$B$10+'1. Assumptions'!$B$11)+(1/$E$6)*'1. Assumptions'!$B$9)) | J26: =G26-$B$26 | K26: ='1. Assumptions'!$E$7*($C$6*(1+'1. Assumptions'!$B$10+'1. Assumptions'!$B$11)+(1/$E$6)*'1. Assumptions'!$E$9) | L26: ='1. Assumptions'!$E$7*($C$6*(1+'1. Assumptions'!$B$10+'1. Assumptions'!$B$11)+(1/$E$6)*'1. Assumptions'!$B$9)-$B$26 | M26: =K26-('1. Assumptions'!$E$7*($C$6*(1+'1. Assumptions'!$B$10+'1. Assumptions'!$B$11)+(1/$E$6)*'1. Assumptions'!$B$9)) | N26: =K26-$B$26
A27: =$A$7 | B27: ='1. Assumptions'!$B$7*($C$7*(1+'1. Assumptions'!$B$10+'1. Assumptions'!$B$11)+(1/$E$7)*'1. Assumptions'!$B$9) | C27: ='1. Assumptions'!$C$7*($C$7*(1+'1. Assumptions'!$B$10+'1. Assumptions'!$B$11)+(1/$E$7)*'1. Assumptions'!$C$9) | D27: ='1. Assumptions'!$C$7*($C$7*(1+'1. Assumptions'!$B$10+'1. Assumptions'!$B$11)+(1/$E$7)*'1. Assumptions'!$B$9)-$B$27 | E27: =C27-('1. Assumptions'!$C$7*($C$7*(1+'1. Assumptions'!$B$10+'1. Assumptions'!$B$11)+(1/$E$7)*'1. Assumptions'!$B$9)) | F27: =C27-$B$27 | G27: ='1. Assumptions'!$D$7*($C$7*(1+'1. Assumptions'!$B$10+'1. Assumptions'!$B$11)+(1/$E$7)*'1. Assumptions'!$D$9) | H27: ='1. Assumptions'!$D$7*($C$7*(1+'1. Assumptions'!$B$10+'1. Assumptions'!$B$11)+(1/$E$7)*'1. Assumptions'!$B$9)-$B$27 | I27: =G27-('1. Assumptions'!$D$7*($C$7*(1+'1. Assumptions'!$B$10+'1. Assumptions'!$B$11)+(1/$E$7)*'1. Assumptions'!$B$9)) | J27: =G27-$B$27 | K27: ='1. Assumptions'!$E$7*($C$7*(1+'1. Assumptions'!$B$10+'1. Assumptions'!$B$11)+(1/$E$7)*'1. Assumptions'!$E$9) | L27: ='1. Assumptions'!$E$7*($C$7*(1+'1. Assumptions'!$B$10+'1. Assumptions'!$B$11)+(1/$E$7)*'1. Assumptions'!$B$9)-$B$27 | M27: =K27-('1. Assumptions'!$E$7*($C$7*(1+'1. Assumptions'!$B$10+'1. Assumptions'!$B$11)+(1/$E$7)*'1. Assumptions'!$B$9)) | N27: =K27-$B$27
A28: =$A$8 | B28: ='1. Assumptions'!$B$7*($C$8*(1+'1. Assumptions'!$B$10+'1. Assumptions'!$B$11)+(1/$E$8)*'1. Assumptions'!$B$9) | C28: ='1. Assumptions'!$C$7*($C$8*(1+'1. Assumptions'!$B$10+'1. Assumptions'!$B$11)+(1/$E$8)*'1. Assumptions'!$C$9) | D28: ='1. Assumptions'!$C$7*($C$8*(1+'1. Assumptions'!$B$10+'1. Assumptions'!$B$11)+(1/$E$8)*'1. Assumptions'!$B$9)-$B$28 | E28: =C28-('1. Assumptions'!$C$7*($C$8*(1+'1. Assumptions'!$B$10+'1. Assumptions'!$B$11)+(1/$E$8)*'1. Assumptions'!$B$9)) | F28: =C28-$B$28 | G28: ='1. Assumptions'!$D$7*($C$8*(1+'1. Assumptions'!$B$10+'1. Assumptions'!$B$11)+(1/$E$8)*'1. Assumptions'!$D$9) | H28: ='1. Assumptions'!$D$7*($C$8*(1+'1. Assumptions'!$B$10+'1. Assumptions'!$B$11)+(1/$E$8)*'1. Assumptions'!$B$9)-$B$28 | I28: =G28-('1. Assumptions'!$D$7*($C$8*(1+'1. Assumptions'!$B$10+'1. Assumptions'!$B$11)+(1/$E$8)*'1. Assumptions'!$B$9)) | J28: =G28-$B$28 | K28: ='1. Assumptions'!$E$7*($C$8*(1+'1. Assumptions'!$B$10+'1. Assumptions'!$B$11)+(1/$E$8)*'1. Assumptions'!$E$9) | L28: ='1. Assumptions'!$E$7*($C$8*(1+'1. Assumptions'!$B$10+'1. Assumptions'!$B$11)+(1/$E$8)*'1. Assumptions'!$B$9)-$B$28 | M28: =K28-('1. Assumptions'!$E$7*($C$8*(1+'1. Assumptions'!$B$10+'1. Assumptions'!$B$11)+(1/$E$8)*'1. Assumptions'!$B$9)) | N28: =K28-$B$28
A29: =$A$9 | B29: ='1. Assumptions'!$B$7*($C$9*(1+'1. Assumptions'!$B$10+'1. Assumptions'!$B$11)+(1/$E$9)*'1. Assumptions'!$B$9) | C29: ='1. Assumptions'!$C$7*($C$9*(1+'1. Assumptions'!$B$10+'1. Assumptions'!$B$11)+(1/$E$9)*'1. Assumptions'!$C$9) | D29: ='1. Assumptions'!$C$7*($C$9*(1+'1. Assumptions'!$B$10+'1. Assumptions'!$B$11)+(1/$E$9)*'1. Assumptions'!$B$9)-$B$29 | E29: =C29-('1. Assumptions'!$C$7*($C$9*(1+'1. Assumptions'!$B$10+'1. Assumptions'!$B$11)+(1/$E$9)*'1. Assumptions'!$B$9)) | F29: =C29-$B$29 | G29: ='1. Assumptions'!$D$7*($C$9*(1+'1. Assumptions'!$B$10+'1. Assumptions'!$B$11)+(1/$E$9)*'1. Assumptions'!$D$9) | H29: ='1. Assumptions'!$D$7*($C$9*(1+'1. Assumptions'!$B$10+'1. Assumptions'!$B$11)+(1/$E$9)*'1. Assumptions'!$B$9)-$B$29 | I29: =G29-('1. Assumptions'!$D$7*($C$9*(1+'1. Assumptions'!$B$10+'1. Assumptions'!$B$11)+(1/$E$9)*'1. Assumptions'!$B$9)) | J29: =G29-$B$29 | K29: ='1. Assumptions'!$E$7*($C$9*(1+'1. Assumptions'!$B$10+'1. Assumptions'!$B$11)+(1/$E$9)*'1. Assumptions'!$E$9) | L29: ='1. Assumptions'!$E$7*($C$9*(1+'1. Assumptions'!$B$10+'1. Assumptions'!$B$11)+(1/$E$9)*'1. Assumptions'!$B$9)-$B$29 | M29: =K29-('1. Assumptions'!$E$7*($C$9*(1+'1. Assumptions'!$B$10+'1. Assumptions'!$B$11)+(1/$E$9)*'1. Assumptions'!$B$9)) | N29: =K29-$B$29
A30: =$A$10 | B30: ='1. Assumptions'!$B$7*($C$10*(1+'1. Assumptions'!$B$10+'1. Assumptions'!$B$11)+(1/$E$10)*'1. Assumptions'!$B$9) | C30: ='1. Assumptions'!$C$7*($C$10*(1+'1. Assumptions'!$B$10+'1. Assumptions'!$B$11)+(1/$E$10)*'1. Assumptions'!$C$9) | D30: ='1. Assumptions'!$C$7*($C$10*(1+'1. Assumptions'!$B$10+'1. Assumptions'!$B$11)+(1/$E$10)*'1. Assumptions'!$B$9)-$B$30 | E30: =C30-('1. Assumptions'!$C$7*($C$10*(1+'1. Assumptions'!$B$10+'1. Assumptions'!$B$11)+(1/$E$10)*'1. Assumptions'!$B$9)) | F30: =C30-$B$30 | G30: ='1. Assumptions'!$D$7*($C$10*(1+'1. Assumptions'!$B$10+'1. Assumptions'!$B$11)+(1/$E$10)*'1. Assumptions'!$D$9) | H30: ='1. Assumptions'!$D$7*($C$10*(1+'1. Assumptions'!$B$10+'1. Assumptions'!$B$11)+(1/$E$10)*'1. Assumptions'!$B$9)-$B$30 | I30: =G30-('1. Assumptions'!$D$7*($C$10*(1+'1. Assumptions'!$B$10+'1. Assumptions'!$B$11)+(1/$E$10)*'1. Assumptions'!$B$9)) | J30: =G30-$B$30 | K30: ='1. Assumptions'!$E$7*($C$10*(1+'1. Assumptions'!$B$10+'1. Assumptions'!$B$11)+(1/$E$10)*'1. Assumptions'!$E$9) | L30: ='1. Assumptions'!$E$7*($C$10*(1+'1. Assumptions'!$B$10+'1. Assumptions'!$B$11)+(1/$E$10)*'1. Assumptions'!$B$9)-$B$30 | M30: =K30-('1. Assumptions'!$E$7*($C$10*(1+'1. Assumptions'!$B$10+'1. Assumptions'!$B$11)+(1/$E$10)*'1. Assumptions'!$B$9)) | N30: =K30-$B$30
A31: =$A$11 | B31: ='1. Assumptions'!$B$7*($C$11*(1+'1. Assumptions'!$B$10+'1. Assumptions'!$B$11)+(1/$E$11)*'1. Assumptions'!$B$9) | C31: ='1. Assumptions'!$C$7*($C$11*(1+'1. Assumptions'!$B$10+'1. Assumptions'!$B$11)+(1/$E$11)*'1. Assumptions'!$C$9) | D31: ='1. Assumptions'!$C$7*($C$11*(1+'1. Assumptions'!$B$10+'1. Assumptions'!$B$11)+(1/$E$11)*'1. Assumptions'!$B$9)-$B$31 | E31: =C31-('1. Assumptions'!$C$7*($C$11*(1+'1. Assumptions'!$B$10+'1. Assumptions'!$B$11)+(1/$E$11)*'1. Assumptions'!$B$9)) | F31: =C31-$B$31 | G31: ='1. Assumptions'!$D$7*($C$11*(1+'1. Assumptions'!$B$10+'1. Assumptions'!$B$11)+(1/$E$11)*'1. Assumptions'!$D$9) | H31: ='1. Assumptions'!$D$7*($C$11*(1+'1. Assumptions'!$B$10+'1. Assumptions'!$B$11)+(1/$E$11)*'1. Assumptions'!$B$9)-$B$31 | I31: =G31-('1. Assumptions'!$D$7*($C$11*(1+'1. Assumptions'!$B$10+'1. Assumptions'!$B$11)+(1/$E$11)*'1. Assumptions'!$B$9)) | J31: =G31-$B$31 | K31: ='1. Assumptions'!$E$7*($C$11*(1+'1. Assumptions'!$B$10+'1. Assumptions'!$B$11)+(1/$E$11)*'1. Assumptions'!$E$9) | L31: ='1. Assumptions'!$E$7*($C$11*(1+'1. Assumptions'!$B$10+'1. Assumptions'!$B$11)+(1/$E$11)*'1. Assumptions'!$B$9)-$B$31 | M31: =K31-('1. Assumptions'!$E$7*($C$11*(1+'1. Assumptions'!$B$10+'1. Assumptions'!$B$11)+(1/$E$11)*'1. Assumptions'!$B$9)) | N31: =K31-$B$31
A32: Average | B32: =AVERAGE(B26:B31) | C32: =AVERAGE(C26:C31) | D32: =AVERAGE(D26:D31) | E32: =AVERAGE(E26:E31) | F32: =AVERAGE(F26:F31) | G32: =AVERAGE(G26:G31) | H32: =AVERAGE(H26:H31) | I32: =AVERAGE(I26:I31) | ... N32: =AVERAGE(N26:N31)
A34: Read it like this: under Severe, compare each SKU's FX Δ against its Freight Δ to see which shock is doing the damage. Light, high-value SKUs are FX-led; bulky, heavy SKUs are freight-led.

Sheet 3. Revenue Scenario
A1: Revenue Scenario — Monthly by Segment, Elasticity-Driven
A2: Scenario revenue = Plan × (1 + consumer-spending move × segment elasticity). Price is held constant, so the move is pure volume. Variance columns are scenario minus plan (negatives in red).
A4: PREMIUM SEGMENT
A5: Month | B5: Plan (AUD) | C5: Base | D5: Moderate | E5: Severe | F5: Var Base | G5: Var Moderate | H5: Var Severe
A6: Sep 2026 | B6: 180000 | C6: =$B6*(1+'1. Assumptions'!$C$12*'1. Assumptions'!$B$17) | D6: =$B6*(1+'1. Assumptions'!$D$12*'1. Assumptions'!$B$17) | E6: =$B6*(1+'1. Assumptions'!$E$12*'1. Assumptions'!$B$17) | F6: =C6-$B6 | G6: =D6-$B6 | H6: =E6-$B6
A7: Oct 2026 | B7: 189000 | C7: =$B7*(1+'1. Assumptions'!$C$12*'1. Assumptions'!$B$17) | D7: =$B7*(1+'1. Assumptions'!$D$12*'1. Assumptions'!$B$17) | E7: =$B7*(1+'1. Assumptions'!$E$12*'1. Assumptions'!$B$17) | F7: =C7-$B7 | G7: =D7-$B7 | H7: =E7-$B7
A8: Nov 2026 | B8: 234000 | C8: =$B8*(1+'1. Assumptions'!$C$12*'1. Assumptions'!$B$17) | D8: =$B8*(1+'1. Assumptions'!$D$12*'1. Assumptions'!$B$17) | E8: =$B8*(1+'1. Assumptions'!$E$12*'1. Assumptions'!$B$17) | F8: =C8-$B8 | G8: =D8-$B8 | H8: =E8-$B8
A9: Dec 2026 | B9: 243000 | C9: =$B9*(1+'1. Assumptions'!$C$12*'1. Assumptions'!$B$17) | D9: =$B9*(1+'1. Assumptions'!$D$12*'1. Assumptions'!$B$17) | E9: =$B9*(1+'1. Assumptions'!$E$12*'1. Assumptions'!$B$17) | F9: =C9-$B9 | G9: =D9-$B9 | H9: =E9-$B9
A10: Jan 2027 | B10: 144000 | C10: =$B10*(1+'1. Assumptions'!$C$12*'1. Assumptions'!$B$17) | D10: =$B10*(1+'1. Assumptions'!$D$12*'1. Assumptions'!$B$17) | E10: =$B10*(1+'1. Assumptions'!$E$12*'1. Assumptions'!$B$17) | F10: =C10-$B10 | G10: =D10-$B10 | H10: =E10-$B10
A11: Feb 2027 | B11: 153000 | C11: =$B11*(1+'1. Assumptions'!$C$12*'1. Assumptions'!$B$17) | D11: =$B11*(1+'1. Assumptions'!$D$12*'1. Assumptions'!$B$17) | E11: =$B11*(1+'1. Assumptions'!$E$12*'1. Assumptions'!$B$17) | F11: =C11-$B11 | G11: =D11-$B11 | H11: =E11-$B11
A12: Mar 2027 | B12: 171000 | C12: =$B12*(1+'1. Assumptions'!$C$12*'1. Assumptions'!$B$17) | D12: =$B12*(1+'1. Assumptions'!$D$12*'1. Assumptions'!$B$17) | E12: =$B12*(1+'1. Assumptions'!$E$12*'1. Assumptions'!$B$17) | F12: =C12-$B12 | G12: =D12-$B12 | H12: =E12-$B12
A13: Apr 2027 | B13: 180000 | C13: =$B13*(1+'1. Assumptions'!$C$12*'1. Assumptions'!$B$17) | D13: =$B13*(1+'1. Assumptions'!$D$12*'1. Assumptions'!$B$17) | E13: =$B13*(1+'1. Assumptions'!$E$12*'1. Assumptions'!$B$17) | F13: =C13-$B13 | G13: =D13-$B13 | H13: =E13-$B13
A14: May 2027 | B14: 189000 | C14: =$B14*(1+'1. Assumptions'!$C$12*'1. Assumptions'!$B$17) | D14: =$B14*(1+'1. Assumptions'!$D$12*'1. Assumptions'!$B$17) | E14: =$B14*(1+'1. Assumptions'!$E$12*'1. Assumptions'!$B$17) | F14: =C14-$B14 | G14: =D14-$B14 | H14: =E14-$B14
A15: Jun 2027 | B15: 198000 | C15: =$B15*(1+'1. Assumptions'!$C$12*'1. Assumptions'!$B$17) | D15: =$B15*(1+'1. Assumptions'!$D$12*'1. Assumptions'!$B$17) | E15: =$B15*(1+'1. Assumptions'!$E$12*'1. Assumptions'!$B$17) | F15: =C15-$B15 | G15: =D15-$B15 | H15: =E15-$B15
A16: PREMIUM subtotal | B16: =SUM(B6:B15) | C16: =SUM(C6:C15) | D16: =SUM(D6:D15) | E16: =SUM(E6:E15) | F16: =SUM(F6:F15) | G16: =SUM(G6:G15) | H16: =SUM(H6:H15)
A18: CORE SEGMENT
A19: Month | B19: Plan (AUD) | C19: Base | D19: Moderate | E19: Severe | F19: Var Base | G19: Var Moderate | H19: Var Severe
A20: Sep 2026 | B20: 320000 | C20: =$B20*(1+'1. Assumptions'!$C$12*'1. Assumptions'!$B$18) | D20: =$B20*(1+'1. Assumptions'!$D$12*'1. Assumptions'!$B$18) | E20: =$B20*(1+'1. Assumptions'!$E$12*'1. Assumptions'!$B$18) | F20: =C20-$B20 | G20: =D20-$B20 | H20: =E20-$B20
A21: Oct 2026 | B21: 336000 | C21: =$B21*(1+'1. Assumptions'!$C$12*'1. Assumptions'!$B$18) | D21: =$B21*(1+'1. Assumptions'!$D$12*'1. Assumptions'!$B$18) | E21: =$B21*(1+'1. Assumptions'!$E$12*'1. Assumptions'!$B$18) | F21: =C21-$B21 | G21: =D21-$B21 | H21: =E21-$B21
A22: Nov 2026 | B22: 416000 | C22: =$B22*(1+'1. Assumptions'!$C$12*'1. Assumptions'!$B$18) | D22: =$B22*(1+'1. Assumptions'!$D$12*'1. Assumptions'!$B$18) | E22: =$B22*(1+'1. Assumptions'!$E$12*'1. Assumptions'!$B$18) | F22: =C22-$B22 | G22: =D22-$B22 | H22: =E22-$B22
A23: Dec 2026 | B23: 432000 | C23: =$B23*(1+'1. Assumptions'!$C$12*'1. Assumptions'!$B$18) | D23: =$B23*(1+'1. Assumptions'!$D$12*'1. Assumptions'!$B$18) | E23: =$B23*(1+'1. Assumptions'!$E$12*'1. Assumptions'!$B$18) | F23: =C23-$B23 | G23: =D23-$B23 | H23: =E23-$B23
A24: Jan 2027 | B24: 256000 | C24: =$B24*(1+'1. Assumptions'!$C$12*'1. Assumptions'!$B$18) | D24: =$B24*(1+'1. Assumptions'!$D$12*'1. Assumptions'!$B$18) | E24: =$B24*(1+'1. Assumptions'!$E$12*'1. Assumptions'!$B$18) | F24: =C24-$B24 | G24: =D24-$B24 | H24: =E24-$B24
A25: Feb 2027 | B25: 272000 | C25: =$B25*(1+'1. Assumptions'!$C$12*'1. Assumptions'!$B$18) | D25: =$B25*(1+'1. Assumptions'!$D$12*'1. Assumptions'!$B$18) | E25: =$B25*(1+'1. Assumptions'!$E$12*'1. Assumptions'!$B$18) | F25: =C25-$B25 | G25: =D25-$B25 | H25: =E25-$B25
A26: Mar 2027 | B26: 304000 | C26: =$B26*(1+'1. Assumptions'!$C$12*'1. Assumptions'!$B$18) | D26: =$B26*(1+'1. Assumptions'!$D$12*'1. Assumptions'!$B$18) | E26: =$B26*(1+'1. Assumptions'!$E$12*'1. Assumptions'!$B$18) | F26: =C26-$B26 | G26: =D26-$B26 | H26: =E26-$B26
A27: Apr 2027 | B27: 320000 | C27: =$B27*(1+'1. Assumptions'!$C$12*'1. Assumptions'!$B$18) | D27: =$B27*(1+'1. Assumptions'!$D$12*'1. Assumptions'!$B$18) | E27: =$B27*(1+'1. Assumptions'!$E$12*'1. Assumptions'!$B$18) | F27: =C27-$B27 | G27: =D27-$B27 | H27: =E27-$B27
A28: May 2027 | B28: 336000 | C28: =$B28*(1+'1. Assumptions'!$C$12*'1. Assumptions'!$B$18) | D28: =$B28*(1+'1. Assumptions'!$D$12*'1. Assumptions'!$B$18) | E28: =$B28*(1+'1. Assumptions'!$E$12*'1. Assumptions'!$B$18) | F28: =C28-$B28 | G28: =D28-$B28 | H28: =E28-$B28
A29: Jun 2027 | B29: 352000 | C29: =$B29*(1+'1. Assumptions'!$C$12*'1. Assumptions'!$B$18) | D29: =$B29*(1+'1. Assumptions'!$D$12*'1. Assumptions'!$B$18) | E29: =$B29*(1+'1. Assumptions'!$E$12*'1. Assumptions'!$B$18) | F29: =C29-$B29 | G29: =D29-$B29 | H29: =E29-$B29
A30: CORE subtotal | B30: =SUM(B20:B29) | C30: =SUM(C20:C29) | D30: =SUM(D20:D29) | E30: =SUM(E20:E29) | F30: =SUM(F20:F29) | G30: =SUM(G20:G29) | H30: =SUM(H20:H29)
A32: VALUE SEGMENT
A33: Month | B33: Plan (AUD) | C33: Base | D33: Moderate | E33: Severe | F33: Var Base | G33: Var Moderate | H33: Var Severe
A34: Sep 2026 | B34: 150000 | C34: =$B34*(1+'1. Assumptions'!$C$12*'1. Assumptions'!$B$19) | D34: =$B34*(1+'1. Assumptions'!$D$12*'1. Assumptions'!$B$19) | E34: =$B34*(1+'1. Assumptions'!$E$12*'1. Assumptions'!$B$19) | F34: =C34-$B34 | G34: =D34-$B34 | H34: =E34-$B34
A35: Oct 2026 | B35: 157500 | C35: =$B35*(1+'1. Assumptions'!$C$12*'1. Assumptions'!$B$19) | D35: =$B35*(1+'1. Assumptions'!$D$12*'1. Assumptions'!$B$19) | E35: =$B35*(1+'1. Assumptions'!$E$12*'1. Assumptions'!$B$19) | F35: =C35-$B35 | G35: =D35-$B35 | H35: =E35-$B35
A36: Nov 2026 | B36: 195000 | C36: =$B36*(1+'1. Assumptions'!$C$12*'1. Assumptions'!$B$19) | D36: =$B36*(1+'1. Assumptions'!$D$12*'1. Assumptions'!$B$19) | E36: =$B36*(1+'1. Assumptions'!$E$12*'1. Assumptions'!$B$19) | F36: =C36-$B36 | G36: =D36-$B36 | H36: =E36-$B36
A37: Dec 2026 | B37: 202500 | C37: =$B37*(1+'1. Assumptions'!$C$12*'1. Assumptions'!$B$19) | D37: =$B37*(1+'1. Assumptions'!$D$12*'1. Assumptions'!$B$19) | E37: =$B37*(1+'1. Assumptions'!$E$12*'1. Assumptions'!$B$19) | F37: =C37-$B37 | G37: =D37-$B37 | H37: =E37-$B37
A38: Jan 2027 | B38: 120000 | C38: =$B38*(1+'1. Assumptions'!$C$12*'1. Assumptions'!$B$19) | D38: =$B38*(1+'1. Assumptions'!$D$12*'1. Assumptions'!$B$19) | E38: =$B38*(1+'1. Assumptions'!$E$12*'1. Assumptions'!$B$19) | F38: =C38-$B38 | G38: =D38-$B38 | H38: =E38-$B38
A39: Feb 2027 | B39: 127500 | C39: =$B39*(1+'1. Assumptions'!$C$12*'1. Assumptions'!$B$19) | D39: =$B39*(1+'1. Assumptions'!$D$12*'1. Assumptions'!$B$19) | E39: =$B39*(1+'1. Assumptions'!$E$12*'1. Assumptions'!$B$19) | F39: =C39-$B39 | G39: =D39-$B39 | H39: =E39-$B39
A40: Mar 2027 | B40: 142500 | C40: =$B40*(1+'1. Assumptions'!$C$12*'1. Assumptions'!$B$19) | D40: =$B40*(1+'1. Assumptions'!$D$12*'1. Assumptions'!$B$19) | E40: =$B40*(1+'1. Assumptions'!$E$12*'1. Assumptions'!$B$19) | F40: =C40-$B40 | G40: =D40-$B40 | H40: =E40-$B40
A41: Apr 2027 | B41: 150000 | C41: =$B41*(1+'1. Assumptions'!$C$12*'1. Assumptions'!$B$19) | D41: =$B41*(1+'1. Assumptions'!$D$12*'1. Assumptions'!$B$19) | E41: =$B41*(1+'1. Assumptions'!$E$12*'1. Assumptions'!$B$19) | F41: =C41-$B41 | G41: =D41-$B41 | H41: =E41-$B41
A42: May 2027 | B42: 157500 | C42: =$B42*(1+'1. Assumptions'!$C$12*'1. Assumptions'!$B$19) | D42: =$B42*(1+'1. Assumptions'!$D$12*'1. Assumptions'!$B$19) | E42: =$B42*(1+'1. Assumptions'!$E$12*'1. Assumptions'!$B$19) | F42: =C42-$B42 | G42: =D42-$B42 | H42: =E42-$B42
A43: Jun 2027 | B43: 165000 | C43: =$B43*(1+'1. Assumptions'!$C$12*'1. Assumptions'!$B$19) | D43: =$B43*(1+'1. Assumptions'!$D$12*'1. Assumptions'!$B$19) | E43: =$B43*(1+'1. Assumptions'!$E$12*'1. Assumptions'!$B$19) | F43: =C43-$B43 | G43: =D43-$B43 | H43: =E43-$B43
...

Sheet 4. Margin Bridge
A1: Margin Bridge — Planned Gross Profit to Scenario Gross Profit
A2: Period gross profit (AUD), decomposed into FX, air-freight, sea-freight substitution and demand-volume steps. The four steps sum exactly to the gap between planned and scenario GP.
A4: PLAN ECONOMICS (period)
A5: Item | B5: Value | G5: Notes
A6: Planned units | B6: ='1. Assumptions'!$B$23 | G6: from Assumptions
A7: Planned ASP (AUD) | B7: ='1. Assumptions'!$B$24 | G7: from Assumptions
A8: Planned revenue | B8: =B6*B7 | G8: units × ASP
A9: Product cost / unit | B9: ='1. Assumptions'!$B$25*(1+'1. Assumptions'!$B$10+'1. Assumptions'!$B$11)*'1. Assumptions'!$B$7 | G9: FOB × (1+duty+ins) × AUD/USD
A10: Air freight / unit | B10: ='1. Assumptions'!$B$26*'1. Assumptions'!$B$8*'1. Assumptions'!$B$7 | G10: weight × air rate × AUD/USD
A11: Sea freight / unit | B11: =(1/'1. Assumptions'!$B$27)*'1. Assumptions'!$B$9*'1. Assumptions'!$B$7 | G11: (1/units-per-CBM) × sea rate × AUD/USD
A12: Air share (plan) | B12: ='1. Assumptions'!$B$28 | G12: from Assumptions
A13: Sea share (plan) | B13: =1-B12 | G13: balance
A14: Blended freight / unit | B14: =B12*B10+B13*B11 | G14: mix-weighted
A15: COGS / unit (plan) | B15: =B9+B14 | G15: product + freight
A16: Planned COGS | B16: =B6*B15 | G16: units × COGS/unit
A17: Planned gross profit | B17: =B8-B16 | G17: revenue − COGS
A18: Planned gross margin % | B18: =B17/B8 | G18: GP / revenue
A20: SCENARIO BRIDGE (period, AUD)
A21: Bridge line | C21: Base | D21: Moderate | E21: Severe | G21: Notes
A22: FX ratio (scen ÷ plan AUD/USD) | C22: ='1. Assumptions'!$C$7/'1. Assumptions'!$B$7 | D22: ='1. Assumptions'!$D$7/'1. Assumptions'!$B$7 | E22: ='1. Assumptions'!$E$7/'1. Assumptions'!$B$7 | G22: revaluation factor on USD costs
A23: Air rate ratio | C23: ='1. Assumptions'!$C$8/'1. Assumptions'!$B$8 | D23: ='1. Assumptions'!$D$8/'1. Assumptions'!$B$8 | E23: ='1. Assumptions'!$E$8/'1. Assumptions'!$B$8
A24: Sea rate ratio | C24: ='1. Assumptions'!$C$9/'1. Assumptions'!$B$9 | D24: ='1. Assumptions'!$D$9/'1. Assumptions'!$B$9 | E24: ='1. Assumptions'!$E$9/'1. Assumptions'!$B$9
A25: Air share (scenario) | C25: =$B$12-'1. Assumptions'!$C$13 | D25: =$B$12-'1. Assumptions'!$D$13 | E25: =$B$12-'1. Assumptions'!$E$13 | G25: plan air share less substitution shift
A26: Sea share (scenario) | C26: =1-C25 | D26: =1-D25 | E26: =1-E25
A27: Demand factor (scen ÷ plan rev) | C27: ='3. Revenue Scenario'!$C$58/'3. Revenue Scenario'!$B$58 | D27: ='3. Revenue Scenario'!$D$58/'3. Revenue Scenario'!$B$58 | E27: ='3. Revenue Scenario'!$E$58/'3. Revenue Scenario'!$B$58 | G27: from Revenue Scenario period totals
A28: c0 COGS/unit @ plan | C28: =$B$15 | D28: =$B$15 | E28: =$B$15
A29: Product/unit @ scenario | C29: =$B$9*C22 | D29: =$B$9*D22 | E29: =$B$9*E22 | G29: plan × FX ratio
A30: Air freight/unit @ scenario | C30: =$B$10*C22*C23 | D30: =$B$10*D22*D23 | E30: =$B$10*E22*E23 | G30: plan × FX × air-rate ratio
A31: Sea freight/unit @ scenario | C31: =$B$11*C22*C24 | D31: =$B$11*D22*D24 | E31: =$B$11*E22*E24 | G31: plan × FX × sea-rate ratio
A32: c1 after FX | C32: =C28*C22 | D32: =D28*D22 | E32: =E28*E22
A33: c2 after air rate | C33: =C29+$B$12*C30+$B$13*($B$11*C22) | D33: =D29+$B$12*D30+$B$13*($B$11*D22) | E33: =E29+$B$12*E30+$B$13*($B$11*E22)
A34: c3 after sea sub (=scen COGS/u) | C34: =C29+C25*C30+C26*C31 | D34: =D29+D25*D30+D26*D31 | E34: =E29+E25*E30+E26*E31
A35: STEP — FX effect | C35: =-$B$6*(C32-C28) | D35: =-$B$6*(D32-D28) | E35: =-$B$6*(E32-E28)
A36: STEP — Air freight | C36: =-$B$6*(C33-C32) | D36: =-$B$6*(D33-D32) | E36: =-$B$6*(E33-E32)
A37: STEP — Sea freight substitution | C37: =-$B$6*(C34-C33) | D37: =-$B$6*(D34-D33) | E37: =-$B$6*(E34-E33)
A38: STEP — Demand volume | C38: =(C27-1)*($B$8-$B$6*C34) | D38: =(D27-1)*($B$8-$B$6*D34) | E38: =(E27-1)*($B$8-$B$6*E34)
A39: Scenario gross profit | B39: Plan GP → | C39: =$B$17+C35+C36+C37+C38 | D39: =$B$17+D35+D36+D37+D38 | E39: =$B$17+E35+E36+E37+E38
A40: Scenario revenue | C40: =$B$8*C27 | D40: =$B$8*D27 | E40: =$B$8*E27
A41: Scenario COGS | C41: =$B$6*C27*C34 | D41: =$B$6*D27*D34 | E41: =$B$6*E27*E34
A42: Scenario gross margin % | C42: =C39/C40 | D42: =D39/D40 | E42: =E39/E40
...

Sheet 5. Mitigation Levers
A1: Mitigation Levers — Closing the Gap
A2: Each lever is modelled against the selected scenario's gross-profit gap. Change the yellow scenario selector and the blue lever settings (X, Y, Z); the residual updates so you can find the combination that closes the gap.
A4: SCENARIO
A5: Scenario: | B5: Severe | C5: ← pick Base / Moderate / Severe
A6: Scenario column index | B6: =MATCH($B$5,'4. Margin Bridge'!$C$21:$E$21,0)
A7: Scenario gross profit | B7: =INDEX('4. Margin Bridge'!$C$39:$E$39,1,$B$6)
A8: Planned gross profit | B8: ='4. Margin Bridge'!$B$17
A9: Gap to plan (scenario − plan) | B9: =B7-B8 | D9: the gap the levers must close
A10: Scenario units | B10: =INDEX('4. Margin Bridge'!$C$43:$E$43,1,$B$6)
A11: Air freight / unit (scen) | B11: =INDEX('4. Margin Bridge'!$C$30:$E$30,1,$B$6)
A12: Sea freight / unit (scen) | B12: =INDEX('4. Margin Bridge'!$C$31:$E$31,1,$B$6)
A13: FX cost @ scenario volume | B13: =INDEX('4. Margin Bridge'!$C$44:$E$44,1,$B$6)
A14: Scenario revenue | B14: =INDEX('4. Margin Bridge'!$C$40:$E$40,1,$B$6)
A15: Scenario COGS | B15: =INDEX('4. Margin Bridge'!$C$41:$E$41,1,$B$6)
A16: Price elasticity | B16: ='1. Assumptions'!$B$29
A17: Scenario air share (cap for X) | B17: =INDEX('4. Margin Bridge'!$C$25:$E$25,1,$B$6)
A18: MITIGATION LEVERS
A19: Lever | B19: Setting | C19: Modelled GP impact (AUD) | D19: How it is modelled
A20: A. Shift volume to sea | B20: 0.12 | C20: =B20*$B$10*($B$11-$B$12) | D20: X% of scenario units moved air→sea × (air − sea) freight/unit. Keep X ≤ scenario air share (B17).
A21: B. Forward-hedge USD exposure | B21: 0.75 | C21: =B21*$B$13 | D21: Y% of the scenario FX cost locked at the plan rate (hedge cost ignored).
A22: C. Pass through price increase | B22: 0.06 | C22: =$B$14*((1+B22)*(1-B22*$B$16)-1)+$B$15*B22*$B$16 | D22: Z% price rise on scenario revenue, less the volume lost at price elasticity; COGS falls with volume.
A24: Combined lever impact | C24: =SUM(C20:C22)
A25: Scenario GP after levers | C25: =B7+C24
A26: Residual vs plan | C26: =C25-B8
A27: Gap closed? | C27: =IF(C26>=0,"YES — gap closed","NO — shortfall remaining")
A29: Tip: levers are shown standalone (second-order interactions are small and ignored). Combine them until Residual vs plan turns green.
